<?xml version="1.0"?>
<robot name="myrobot" xmlns:xacro="http://www.ros.org/wiki/xacro">

  <!-- Properties -->
  <xacro:property name="cameraSize" value="0.05"/>
  <xacro:property name="cameraMass" value="0.1"/>

  <!-- Gazebo extensions -->
  <xacro:include filename="$(find my_robot)/urdf/robot.gazebo"/>

  <!-- Chassis -->
  <link name="chassis">
    <visual name="chassis_visual">
      <origin xyz="0 0 0" rpy="0 0 0"/>
      <geometry>
        <box size="0.4 0.2 0.1"/>
      </geometry>
      <material name="green">
        <color rgba="0 0.9 0.2 1"/>
      </material>
    </visual>

    <inertial>
      <mass value="10.0"/>
      <origin xyz="0.0 0 0.1" rpy="0 0 0"/>
      <inertia
          ixx="0.5" ixy="0" ixz="0"
          iyy="1.0" iyz="0"
          izz="0.1"/>
    </inertial>

    <collision name="chassis_collision">
      <geometry>
        <box size="0.4 0.2 0.1"/>
      </geometry>
    </collision>
  </link>

  <!-- Caster wheel -->
  <link name="caster">
    <collision name="caster_collision">
      <origin xyz="0 0 0" rpy="0 0 0"/>
      <geometry>
        <sphere radius="0.05"/>
      </geometry>
      <surface>
        <friction>
          <ode>
            <mu>0</mu>
            <mu2>0</mu2>
            <slip1>1.0</slip1>
            <slip2>1.0</slip2>
          </ode>
        </friction>
      </surface>
    </collision>

    <visual name="caster_visual">
      <origin xyz="0 0 0" rpy="0 0 0"/>
      <geometry>
        <sphere radius="0.05"/>
      </geometry>
    </visual>
  </link>

  <!-- Caster joint -->
  <joint name="joint_caster" type="fixed">
    <parent link="chassis"/>
    <child link="caster"/>
    <origin xyz="-0.15 0 -0.05" rpy="0 0 0"/>
  </joint>

  <!-- Left wheel -->
  <link name="left_wheel">
    <collision name="left_wheel_collision">
      <origin xyz="0 0 0" rpy="0 1.5707 1.5707"/>
      <geometry>
        <cylinder radius="0.1" length="0.05"/>
      </geometry>
    </collision>

    <visual name="left_wheel_visual">
      <origin xyz="0 0 0" rpy="0 1.5707 1.5707"/>
      <geometry>
        <cylinder radius="0.1" length="0.05"/>
      </geometry>
      <material name="gray">
        <color rgba="0.4 0.4 0.4 1"/>
      </material>
    </visual>

    <inertial>
      <origin xyz="0 0 0" rpy="0 1.5707 1.5707"/>
      <mass value="5"/>
      <inertia
        ixx="1.0" ixy="0.0" ixz="0.0"
        iyy="1.0" iyz="0.0"
        izz="1.0"/>
    </inertial>
  </link>

  <!-- Right wheel -->
  <link name="right_wheel">
    <collision name="right_wheel_collision">
      <origin xyz="0 0 0" rpy="0 1.5707 1.5707"/>
      <geometry>
        <cylinder radius="0.1" length="0.05"/>
      </geometry>
    </collision>

    <visual name="right_wheel_visual">
      <origin xyz="0 0 0" rpy="0 1.5707 1.5707"/>
      <geometry>
        <cylinder radius="0.1" length="0.05"/>
      </geometry>
      <material name="gray">
        <color rgba="0.4 0.4 0.4 1"/>
      </material>
    </visual>

    <inertial>
      <origin xyz="0 0 0" rpy="0 1.5707 1.5707"/>
      <mass value="5"/>
      <inertia
        ixx="1.0" ixy="0.0" ixz="0.0"
        iyy="1.0" iyz="0.0"
        izz="1.0"/>
    </inertial>
  </link>

  <!-- Left wheel joint -->
  <joint type="continuous" name="left_wheel_hinge">
    <origin xyz="0.1 0.15 0" rpy="0 0 0"/>
    <child link="left_wheel"/>
    <parent link="chassis"/>
    <axis xyz="0 1 0" rpy="0 0 0"/>
    <limit effort="100" velocity="100"/>
    <joint_properties damping="0.0" friction="0.0"/>
  </joint>

  <!-- Right wheel joint -->
  <joint type="continuous" name="right_wheel_hinge">
    <origin xyz="0.1 -0.15 0" rpy="0 0 0"/>
    <child link="right_wheel"/>
    <parent link="chassis"/>
    <axis xyz="0 1 0" rpy="0 0 0"/>
    <limit effort="100" velocity="100"/>
    <joint_properties damping="0.0" friction="0.0"/>
  </joint>

  <!-- Camera link -->
  <link name="camera">
    <collision>
      <origin xyz="0 0 0" rpy="0 0 0"/>
      <geometry>
        <box size="${cameraSize} ${cameraSize} ${cameraSize}"/>
      </geometry>
    </collision>

    <visual>
      <origin xyz="0 0 0" rpy="0 0 0"/>
      <geometry>
        <box size="${cameraSize} ${cameraSize} ${cameraSize}"/>
      </geometry>
      <material name="white"/>
    </visual>

    <inertial>
      <mass value="${cameraMass}"/>
      <origin xyz="0 0 0" rpy="0 0 0"/>
      <inertia ixx="1e-6" ixy="0" ixz="0" iyy="1e-6" iyz="0" izz="1e-6"/>
    </inertial>
  </link>

  <!-- Camera joint -->
  <joint name="camera_joint" type="fixed">
    <axis xyz="0 1 0"/>
    <origin xyz="0.2 0 0" rpy="0 0 0"/>
    <parent link="chassis"/>
    <child link="camera"/>
  </joint>

  <!-- Hokuyo joint -->
  <joint name="hokuyo_joint" type="fixed">
    <axis xyz="0 1 0"/>
    <origin xyz="0.15 0 0.1" rpy="0 0 0"/>
    <parent link="chassis"/>
    <child link="hokuyo"/>
  </joint>

  <!-- Hokuyo Laser -->
  <link name="hokuyo">
    <collision>
      <origin xyz="0 0 0" rpy="0 0 0"/>
      <geometry>
        <box size="0.1 0.1 0.1"/>
      </geometry>
    </collision>

    <visual>
      <origin xyz="0 0 0" rpy="0 0 0"/>
      <geometry>
        <mesh filename="file://$(find my_robot)/meshes/hokuyo.dae"/>
      </geometry>
    </visual>

    <inertial>
      <mass value="1e-5"/>
      <origin xyz="0 0 0" rpy="0 0 0"/>
      <inertia ixx="1e-6" ixy="0" ixz="0" iyy="1e-6" iyz="0" izz="1e-6"/>
    </inertial>
  </link>

</robot>

